{
  "nbformat": 4,
  "nbformat_minor": 0,
  "metadata": {
    "colab": {
      "name": "Exceptions.ipynb",
      "version": "0.3.2",
      "provenance": [],
      "collapsed_sections": [],
      "include_colab_link": true
    },
    "kernelspec": {
      "display_name": "Python 3",
      "language": "python",
      "name": "python3"
    }
  },
  "cells": [
    {
      "cell_type": "markdown",
      "metadata": {
        "id": "view-in-github",
        "colab_type": "text"
      },
      "source": [
        "<a href=\"https://colab.research.google.com/github/fstennet/Python-TAC/blob/master/Exceptions.ipynb\" target=\"_parent\"><img src=\"https://colab.research.google.com/assets/colab-badge.svg\" alt=\"Open In Colab\"/></a>"
      ]
    },
    {
      "metadata": {
        "id": "VdqZ5asEyDG7",
        "colab_type": "text"
      },
      "cell_type": "markdown",
      "source": [
        "# Exceptions\n",
        "\n",
        "Even if a statement or expression is syntactically correct, **it may cause an error when an attempt is made to execute it**. Errors detected during execution are called **exceptions** and are not unconditionally fatal: you will soon learn how to handle them in Python programs. Most exceptions are not handled by programs, however, and result in error messages as shown here:"
      ]
    },
    {
      "metadata": {
        "id": "47wB3-eJyDG8",
        "colab_type": "code",
        "colab": {
          "base_uri": "https://localhost:8080/",
          "height": 163
        },
        "outputId": "a71ed5ca-e35a-4ead-90ff-544ba0b701ae"
      },
      "cell_type": "code",
      "source": [
        "10 * (1/0)"
      ],
      "execution_count": 1,
      "outputs": [
        {
          "output_type": "error",
          "ename": "ZeroDivisionError",
          "evalue": "ignored",
          "traceback": [
            "\u001b[0;31m---------------------------------------------------------------------------\u001b[0m",
            "\u001b[0;31mZeroDivisionError\u001b[0m                         Traceback (most recent call last)",
            "\u001b[0;32m<ipython-input-1-0b280f36835c>\u001b[0m in \u001b[0;36m<module>\u001b[0;34m()\u001b[0m\n\u001b[0;32m----> 1\u001b[0;31m \u001b[0;36m10\u001b[0m \u001b[0;34m*\u001b[0m \u001b[0;34m(\u001b[0m\u001b[0;36m1\u001b[0m\u001b[0;34m/\u001b[0m\u001b[0;36m0\u001b[0m\u001b[0;34m)\u001b[0m\u001b[0;34m\u001b[0m\u001b[0;34m\u001b[0m\u001b[0m\n\u001b[0m",
            "\u001b[0;31mZeroDivisionError\u001b[0m: division by zero"
          ]
        }
      ]
    },
    {
      "metadata": {
        "id": "1kpWfd16yDG_",
        "colab_type": "code",
        "colab": {
          "base_uri": "https://localhost:8080/",
          "height": 163
        },
        "outputId": "55de589f-9fee-47c5-f8f0-0219c2e9b995"
      },
      "cell_type": "code",
      "source": [
        "4 + spam*3"
      ],
      "execution_count": 2,
      "outputs": [
        {
          "output_type": "error",
          "ename": "NameError",
          "evalue": "ignored",
          "traceback": [
            "\u001b[0;31m---------------------------------------------------------------------------\u001b[0m",
            "\u001b[0;31mNameError\u001b[0m                                 Traceback (most recent call last)",
            "\u001b[0;32m<ipython-input-2-c98bb92cdcac>\u001b[0m in \u001b[0;36m<module>\u001b[0;34m()\u001b[0m\n\u001b[0;32m----> 1\u001b[0;31m \u001b[0;36m4\u001b[0m \u001b[0;34m+\u001b[0m \u001b[0mspam\u001b[0m\u001b[0;34m*\u001b[0m\u001b[0;36m3\u001b[0m\u001b[0;34m\u001b[0m\u001b[0;34m\u001b[0m\u001b[0m\n\u001b[0m",
            "\u001b[0;31mNameError\u001b[0m: name 'spam' is not defined"
          ]
        }
      ]
    },
    {
      "metadata": {
        "id": "ArxOJR4JyDHC",
        "colab_type": "code",
        "colab": {
          "base_uri": "https://localhost:8080/",
          "height": 163
        },
        "outputId": "9dba9733-f494-4880-83f6-e00596f71630"
      },
      "cell_type": "code",
      "source": [
        "'2' + 2"
      ],
      "execution_count": 3,
      "outputs": [
        {
          "output_type": "error",
          "ename": "TypeError",
          "evalue": "ignored",
          "traceback": [
            "\u001b[0;31m---------------------------------------------------------------------------\u001b[0m",
            "\u001b[0;31mTypeError\u001b[0m                                 Traceback (most recent call last)",
            "\u001b[0;32m<ipython-input-3-d2b23a1db757>\u001b[0m in \u001b[0;36m<module>\u001b[0;34m()\u001b[0m\n\u001b[0;32m----> 1\u001b[0;31m \u001b[0;34m'2'\u001b[0m \u001b[0;34m+\u001b[0m \u001b[0;36m2\u001b[0m\u001b[0;34m\u001b[0m\u001b[0;34m\u001b[0m\u001b[0m\n\u001b[0m",
            "\u001b[0;31mTypeError\u001b[0m: must be str, not int"
          ]
        }
      ]
    },
    {
      "metadata": {
        "id": "ijQJ0508yDHF",
        "colab_type": "text"
      },
      "cell_type": "markdown",
      "source": [
        "## Handling Exceptions\n",
        "\n",
        "It is possible to write programs that **handle** selected exceptions. Look at the following example, which asks the user for input until a valid integer has been entered, but allows the user to interrupt the program (using Control-C or whatever the operating system supports); note that a user-generated interruption is signalled by raising the KeyboardInterrupt exception."
      ]
    },
    {
      "metadata": {
        "id": "9wYs9hi2yDHG",
        "colab_type": "code",
        "colab": {
          "base_uri": "https://localhost:8080/",
          "height": 102
        },
        "outputId": "5146fc9a-3d47-4d85-a773-f6e200b4d086"
      },
      "cell_type": "code",
      "source": [
        "while True:\n",
        "    try:\n",
        "        x = int(input(\"Please enter a number: \"))\n",
        "        break\n",
        "    except ValueError:\n",
        "        print(\"Oops! That was no valid number. Try again...\")"
      ],
      "execution_count": 4,
      "outputs": [
        {
          "output_type": "stream",
          "text": [
            "Please enter a number: s\\\n",
            "Oops! That was no valid number. Try again...\n",
            "Please enter a number: w\n",
            "Oops! That was no valid number. Try again...\n",
            "Please enter a number: 3\n"
          ],
          "name": "stdout"
        }
      ]
    },
    {
      "metadata": {
        "id": "OWjqjzqjyDHI",
        "colab_type": "text"
      },
      "cell_type": "markdown",
      "source": [
        "The **try** statement works as follows.\n",
        "\n",
        "- First, the **try** clause (the statement(s) between the try and except keywords) is executed.\n",
        "- If **no exception** occurs, the except clause is skipped and execution of the try statement is finished.\n",
        "- If an **exception occurs** during execution of the try clause, the rest of the clause is skipped. Then if its type matches the exception named after the except keyword, the **except clause is executed**, and then execution continues after the try statement.\n",
        "- If an exception occurs which **does not match the exception named** in the except clause, it is passed on to outer try statements; if no handler is found, it is an unhandled exception and execution stops with a message as shown above."
      ]
    }
  ]
}